Workbook

Sheet Liste cible - Plazza
A1: ID Unique | B1: Latitude | C1: Longitude | D1: Fournisseur | E1: Logo | F1: Category | G1: Supplier Site Code | H1: Orange Site Code | I1: Address | J1: City / Country | K1: Proximity Service Description
A2: =IFERROR(Tableau1[[#This Row],[ID Unique]],"") -> CIBUBUE1ARE1 | B2: =IFERROR(VLOOKUP($A2,'Consolidate List'!$A$2:$P$1048576,15,FALSE),"") -> -58.46698190000001 | C2: =IFERROR(VLOOKUP($A2,'Consolidate List'!$A$2:$P$1048576,16,FALSE),"") -> 0 | D2: =IFERROR(VLOOKUP($A2,'Consolidate List'!$A$2:$P$1048576,8,FALSE),"") -> BUEL01 | F2: =IFERROR(VLOOKUP($A2,'Consolidate List'!$A$2:$P$1048576,12,FALSE),"") -> NON | G2: =IFERROR(VLOOKUP($A2,'Consolidate List'!$A$2:$P$1048576,11,FALSE),"") -> 3 - Opportunistic not to promote | H2: =IFERROR(VLOOKUP($A2,'Consolidate List'!$A$2:$P$1048576,9,FALSE),"") -> Av. del Campo 1301, Buenos Aires, Argentine | I2: =IFERROR(VLOOKUP($A2,'Consolidate List'!$A$2:$P$1048576,10,FALSE),"") -> BUE1 | J2: =IFERROR(_xlfn.CONCAT((VLOOKUP($A2,'Consolidate List'!$A$2:$P$1048576,5,FALSE)),", ",VLOOKUP($A2,'Consolidate List'!$A$2:$P$1048576,6,FALSE)),"") -> Buenos Aires, Buenos Aires | K2: =IFERROR(VLOOKUP($A2,'Consolidate List'!$A$2:$P$1048576,17,FALSE),"")
A3: =IFERROR(Tableau1[[#This Row],[ID Unique]],"") -> EQSYNORTAU01 | B3: =IFERROR(VLOOKUP($A3,'Consolidate List'!$A$2:$P$1048576,15,FALSE),"") -> 151.1317254 | C3: =IFERROR(VLOOKUP($A3,'Consolidate List'!$A$2:$P$1048576,16,FALSE),"") -> 0 | D3: =IFERROR(VLOOKUP($A3,'Consolidate List'!$A$2:$P$1048576,8,FALSE),"") -> SYDX01 | F3: =IFERROR(VLOOKUP($A3,'Consolidate List'!$A$2:$P$1048576,12,FALSE),"") -> NON | G3: =IFERROR(VLOOKUP($A3,'Consolidate List'!$A$2:$P$1048576,11,FALSE),"") -> 5 - Closed | H3: =IFERROR(VLOOKUP($A3,'Consolidate List'!$A$2:$P$1048576,9,FALSE),"") -> Unit 8, 5 Talavera Road, Macquarie Park, NSW, 2113 | I3: =IFERROR(VLOOKUP($A3,'Consolidate List'!$A$2:$P$1048576,10,FALSE),"") -> North Ryde SYDX01 | J3: =IFERROR(_xlfn.CONCAT((VLOOKUP($A3,'Consolidate List'!$A$2:$P$1048576,5,FALSE)),", ",VLOOKUP($A3,'Consolidate List'!$A$2:$P$1048576,6,FALSE)),"") -> Sydney, Sydney | K3: =IFERROR(VLOOKUP($A3,'Consolidate List'!$A$2:$P$1048576,17,FALSE),"")
A4: =IFERROR(Tableau1[[#This Row],[ID Unique]],"") -> EQSASP4BRP4 | B4: =IFERROR(VLOOKUP($A4,'Consolidate List'!$A$2:$P$1048576,15,FALSE),"") -> -46.8094334 | C4: =IFERROR(VLOOKUP($A4,'Consolidate List'!$A$2:$P$1048576,16,FALSE),"") -> https://plazza.orange.com/docs/DOC-520558 | D4: =IFERROR(VLOOKUP($A4,'Consolidate List'!$A$2:$P$1048576,8,FALSE),"") -> SAOI01 | F4: =IFERROR(VLOOKUP($A4,'Consolidate List'!$A$2:$P$1048576,12,FALSE),"") -> OUI | G4: =IFERROR(VLOOKUP($A4,'Consolidate List'!$A$2:$P$1048576,11,FALSE),"") -> 2 - Opportunistic | H4: =IFERROR(VLOOKUP($A4,'Consolidate List'!$A$2:$P$1048576,9,FALSE),"") -> Av. Ceci, 1900 - Res. Tambore, Barueri - SP, 06460-120, Brésil | I4: =IFERROR(VLOOKUP($A4,'Consolidate List'!$A$2:$P$1048576,10,FALSE),"") -> SP4 | J4: =IFERROR(_xlfn.CONCAT((VLOOKUP($A4,'Consolidate List'!$A$2:$P$1048576,5,FALSE)),", ",VLOOKUP($A4,'Consolidate List'!$A$2:$P$1048576,6,FALSE)),"") -> Sao Paulo, Sao Paulo | K4: =IFERROR(VLOOKUP($A4,'Consolidate List'!$A$2:$P$1048576,17,FALSE),"")
A5: =IFERROR(Tableau1[[#This Row],[ID Unique]],"") -> EQRIRJ1BRJ1 | B5: =IFERROR(VLOOKUP($A5,'Consolidate List'!$A$2:$P$1048576,15,FALSE),"") -> -43.1945909 | C5: =IFERROR(VLOOKUP($A5,'Consolidate List'!$A$2:$P$1048576,16,FALSE),"") -> https://plazza.orange.com/docs/DOC-520558 | D5: =IFERROR(VLOOKUP($A5,'Consolidate List'!$A$2:$P$1048576,8,FALSE),"") -> not found on GINI | F5: =IFERROR(VLOOKUP($A5,'Consolidate List'!$A$2:$P$1048576,12,FALSE),"") -> OUI | G5: =IFERROR(VLOOKUP($A5,'Consolidate List'!$A$2:$P$1048576,11,FALSE),"") -> 2 - Opportunistic | H5: =IFERROR(VLOOKUP($A5,'Consolidate List'!$A$2:$P$1048576,9,FALSE),"") -> Rua Voluntários da Pátria 360 - Botafogo 22270-010 Rio de Janeiro | I5: =IFERROR(VLOOKUP($A5,'Consolidate List'!$A$2:$P$1048576,10,FALSE),"") -> RJ1 | J5: =IFERROR(_xlfn.CONCAT((VLOOKUP($A5,'Consolidate List'!$A$2:$P$1048576,5,FALSE)),", ",VLOOKUP($A5,'Consolidate List'!$A$2:$P$1048576,6,FALSE)),"") -> Rio de Janeiro, Rio de Janeiro | K5: =IFERROR(VLOOKUP($A5,'Consolidate List'!$A$2:$P$1048576,17,FALSE),"")
A6: =IFERROR(Tableau1[[#This Row],[ID Unique]],"") -> VOBEVDC-AU02 | B6: =IFERROR(VLOOKUP($A6,'Consolidate List'!$A$2:$P$1048576,15,FALSE),"") -> 115.8884299 | C6: =IFERROR(VLOOKUP($A6,'Consolidate List'!$A$2:$P$1048576,16,FALSE),"") -> 0 | D6: =IFERROR(VLOOKUP($A6,'Consolidate List'!$A$2:$P$1048576,8,FALSE),"") -> not found on GINI | F6: =IFERROR(VLOOKUP($A6,'Consolidate List'!$A$2:$P$1048576,12,FALSE),"") -> NON | G6: =IFERROR(VLOOKUP($A6,'Consolidate List'!$A$2:$P$1048576,11,FALSE),"") -> 3 - Opportunistic not to promote | H6: =IFERROR(VLOOKUP($A6,'Consolidate List'!$A$2:$P$1048576,9,FALSE),"") -> Vocus VDC-PER02 Data Centre., 5 Watts Place, Bentley WA 6102, Australia. | I6: =IFERROR(VLOOKUP($A6,'Consolidate List'!$A$2:$P$1048576,10,FALSE),"") -> VDC-PER02 | J6: =IFERROR(_xlfn.CONCAT((VLOOKUP($A6,'Consolidate List'!$A$2:$P$1048576,5,FALSE)),", ",VLOOKUP($A6,'Consolidate List'!$A$2:$P$1048576,6,FALSE)),"") -> Perth, Bently | K6: =IFERROR(VLOOKUP($A6,'Consolidate List'!$A$2:$P$1048576,17,FALSE),"")
A7: =IFERROR(Tableau1[[#This Row],[ID Unique]],"") -> EQSASP2BRP2 | B7: =IFERROR(VLOOKUP($A7,'Consolidate List'!$A$2:$P$1048576,15,FALSE),"") -> -46.8272798 | C7: =IFERROR(VLOOKUP($A7,'Consolidate List'!$A$2:$P$1048576,16,FALSE),"") -> https://plazza.orange.com/docs/DOC-520558 | D7: =IFERROR(VLOOKUP($A7,'Consolidate List'!$A$2:$P$1048576,8,FALSE),"") -> SAOD04 | F7: =IFERROR(VLOOKUP($A7,'Consolidate List'!$A$2:$P$1048576,12,FALSE),"") -> OUI | G7: =IFERROR(VLOOKUP($A7,'Consolidate List'!$A$2:$P$1048576,11,FALSE),"") -> 2 - Opportunistic | H7: =IFERROR(VLOOKUP($A7,'Consolidate List'!$A$2:$P$1048576,9,FALSE),"") -> Al. Araguaia 3641 - Tamboré Barueri - SP CEP: 06455-000 | I7: =IFERROR(VLOOKUP($A7,'Consolidate List'!$A$2:$P$1048576,10,FALSE),"") -> SP2 | J7: =IFERROR(_xlfn.CONCAT((VLOOKUP($A7,'Consolidate List'!$A$2:$P$1048576,5,FALSE)),", ",VLOOKUP($A7,'Consolidate List'!$A$2:$P$1048576,6,FALSE)),"") -> Sao Paulo, Sao Paulo | K7: =IFERROR(VLOOKUP($A7,'Consolidate List'!$A$2:$P$1048576,17,FALSE),"")
A8: =IFERROR(Tableau1[[#This Row],[ID Unique]],"") -> EQSASP3BRP3 | B8: =IFERROR(VLOOKUP($A8,'Consolidate List'!$A$2:$P$1048576,15,FALSE),"") -> -46.86328839999999 | C8: =IFERROR(VLOOKUP($A8,'Consolidate List'!$A$2:$P$1048576,16,FALSE),"") -> https://plazza.orange.com/docs/DOC-520558 | D8: =IFERROR(VLOOKUP($A8,'Consolidate List'!$A$2:$P$1048576,8,FALSE),"") -> GRU01 | F8: =IFERROR(VLOOKUP($A8,'Consolidate List'!$A$2:$P$1048576,12,FALSE),"") -> OUI | G8: =IFERROR(VLOOKUP($A8,'Consolidate List'!$A$2:$P$1048576,11,FALSE),"") -> 2 - Opportunistic | H8: =IFERROR(VLOOKUP($A8,'Consolidate List'!$A$2:$P$1048576,9,FALSE),"") -> Avenida Marcos Penteado de Ulhoa Rodrigues, 249 Santana de Parnaiba/SP CEP: 06543-001 Brazil | I8: =IFERROR(VLOOKUP($A8,'Consolidate List'!$A$2:$P$1048576,10,FALSE),"") -> SP3 | J8: =IFERROR(_xlfn.CONCAT((VLOOKUP($A8,'Consolidate List'!$A$2:$P$1048576,5,FALSE)),", ",VLOOKUP($A8,'Consolidate List'!$A$2:$P$1048576,6,FALSE)),"") -> Sao Paulo, Sao Paulo | K8: =IFERROR(VLOOKUP($A8,'Consolidate List'!$A$2:$P$1048576,17,FALSE),"")
A9: =IFERROR(Tableau1[[#This Row],[ID Unique]],"") -> ADSAADN COSE | B9: =IFERROR(VLOOKUP($A9,'Consolidate List'!$A$2:$P$1048576,15,FALSE),"") -> -84.1857912 | C9: =IFERROR(VLOOKUP($A9,'Consolidate List'!$A$2:$P$1048576,16,FALSE),"") -> To be done | D9: =IFERROR(VLOOKUP($A9,'Consolidate List'!$A$2:$P$1048576,8,FALSE),"") -> SJOL01 | F9: =IFERROR(VLOOKUP($A9,'Consolidate List'!$A$2:$P$1048576,12,FALSE),"") -> OUI | G9: =IFERROR(VLOOKUP($A9,'Consolidate List'!$A$2:$P$1048576,11,FALSE),"") -> 2 - Opportunistic | H9: =IFERROR(VLOOKUP($A9,'Consolidate List'!$A$2:$P$1048576,9,FALSE),"") -> ADN Datacenters, Zona Franca SARET Edificio B8 Alajuela Costa Rica | I9: =IFERROR(VLOOKUP($A9,'Consolidate List'!$A$2:$P$1048576,10,FALSE),"") -> ADN by UFINET - San Jose | J9: =IFERROR(_xlfn.CONCAT((VLOOKUP($A9,'Consolidate List'!$A$2:$P$1048576,5,FALSE)),", ",VLOOKUP($A9,'Consolidate List'!$A$2:$P$1048576,6,FALSE)),"") -> San Jose, San Jose | K9: =IFERROR(VLOOKUP($A9,'Consolidate List'!$A$2:$P$1048576,17,FALSE),"")
A10: =IFERROR(Tableau1[[#This Row],[ID Unique]],"") -> CODADAL3UNL3 | B10: =IFERROR(VLOOKUP($A10,'Consolidate List'!$A$2:$P$1048576,15,FALSE),"") -> -96.819412 | C10: =IFERROR(VLOOKUP($A10,'Consolidate List'!$A$2:$P$1048576,16,FALSE),"") -> To be done | D10: =IFERROR(VLOOKUP($A10,'Consolidate List'!$A$2:$P$1048576,8,FALSE),"") -> DALL02 | F10: =IFERROR(VLOOKUP($A10,'Consolidate List'!$A$2:$P$1048576,12,FALSE),"") -> OUI | G10: =IFERROR(VLOOKUP($A10,'Consolidate List'!$A$2:$P$1048576,11,FALSE),"") -> 2 - Opportunistic | H10: =IFERROR(VLOOKUP($A10,'Consolidate List'!$A$2:$P$1048576,9,FALSE),"") -> 1950 North Stemmons Freeway, Suites 1039A & 2048, Dallas, Texas, United States of America, 75207 | I10: =IFERROR(VLOOKUP($A10,'Consolidate List'!$A$2:$P$1048576,10,FALSE),"") -> DAL3 | J10: =IFERROR(_xlfn.CONCAT((VLOOKUP($A10,'Consolidate List'!$A$2:$P$1048576,5,FALSE)),", ",VLOOKUP($A10,'Consolidate List'!$A$2:$P$1048576,6,FALSE)),"") -> Texas, Dallas | K10: =IFERROR(VLOOKUP($A10,'Consolidate List'!$A$2:$P$1048576,17,FALSE),"")
A11: =IFERROR(Tableau1[[#This Row],[ID Unique]],"") -> COMOMTL7CAL7 | B11: =IFERROR(VLOOKUP($A11,'Consolidate List'!$A$2:$P$1048576,15,FALSE),"") -> 0 | C11: =IFERROR(VLOOKUP($A11,'Consolidate List'!$A$2:$P$1048576,16,FALSE),"") -> 0 | D11: =IFERROR(VLOOKUP($A11,'Consolidate List'!$A$2:$P$1048576,8,FALSE),"") -> n/a | F11: =IFERROR(VLOOKUP($A11,'Consolidate List'!$A$2:$P$1048576,12,FALSE),"") -> OUI | G11: =IFERROR(VLOOKUP($A11,'Consolidate List'!$A$2:$P$1048576,11,FALSE),"") -> 2 - Opportunistic | H11: =IFERROR(VLOOKUP($A11,'Consolidate List'!$A$2:$P$1048576,9,FALSE),"") -> 1155 Blvd. Robert-Bourassa, Montreal, QC H3B 3A7 | I11: =IFERROR(VLOOKUP($A11,'Consolidate List'!$A$2:$P$1048576,10,FALSE),"") -> MTL7 | J11: =IFERROR(_xlfn.CONCAT((VLOOKUP($A11,'Consolidate List'!$A$2:$P$1048576,5,FALSE)),", ",VLOOKUP($A11,'Consolidate List'!$A$2:$P$1048576,6,FALSE)),"") -> Ontario, Montreal | K11: =IFERROR(VLOOKUP($A11,'Consolidate List'!$A$2:$P$1048576,17,FALSE),"")
A12: =IFERROR(Tableau1[[#This Row],[ID Unique]],"") -> COTOTOR1CAR1 | B12: =IFERROR(VLOOKUP($A12,'Consolidate List'!$A$2:$P$1048576,15,FALSE),"") -> 0 | C12: =IFERROR(VLOOKUP($A12,'Consolidate List'!$A$2:$P$1048576,16,FALSE),"") -> 0 | D12: =IFERROR(VLOOKUP($A12,'Consolidate List'!$A$2:$P$1048576,8,FALSE),"") -> n/a | F12: =IFERROR(VLOOKUP($A12,'Consolidate List'!$A$2:$P$1048576,12,FALSE),"") -> OUI | G12: =IFERROR(VLOOKUP($A12,'Consolidate List'!$A$2:$P$1048576,11,FALSE),"") -> 2 - Opportunistic | H12: =IFERROR(VLOOKUP($A12,'Consolidate List'!$A$2:$P$1048576,9,FALSE),"") -> 151 Front St. W, Toronto, ON M5J 2N1 | I12: =IFERROR(VLOOKUP($A12,'Consolidate List'!$A$2:$P$1048576,10,FALSE),"") -> TOR1 | J12: =IFERROR(_xlfn.CONCAT((VLOOKUP($A12,'Consolidate List'!$A$2:$P$1048576,5,FALSE)),", ",VLOOKUP($A12,'Consolidate List'!$A$2:$P$1048576,6,FALSE)),"") -> Ontario, Toronto | K12: =IFERROR(VLOOKUP($A12,'Consolidate List'!$A$2:$P$1048576,17,FALSE),"")
A13: =IFERROR(Tableau1[[#This Row],[ID Unique]],"") -> MOBRSTUABEDC | B13: =IFERROR(VLOOKUP($A13,'Consolidate List'!$A$2:$P$1048576,15,FALSE),"") -> 4.5035326 | C13: =IFERROR(VLOOKUP($A13,'Consolidate List'!$A$2:$P$1048576,16,FALSE),"") -> 0 | D13: =IFERROR(VLOOKUP($A13,'Consolidate List'!$A$2:$P$1048576,8,FALSE),"") -> BRUT03 | F13: =IFERROR(VLOOKUP($A13,'Consolidate List'!$A$2:$P$1048576,12,FALSE),"") -> NON | G13: =IFERROR(VLOOKUP($A13,'Consolidate List'!$A$2:$P$1048576,11,FALSE),"") -> 3 - Opportunistic not to promote | H13: =IFERROR(VLOOKUP($A13,'Consolidate List'!$A$2:$P$1048576,9,FALSE),"") -> Mobistar Datacenter Nossegem Leuvensesteenweg 641,1930 Zaventem, Belgium | I13: =IFERROR(VLOOKUP($A13,'Consolidate List'!$A$2:$P$1048576,10,FALSE),"") -> Stuart DC | J13: =IFERROR(_xlfn.CONCAT((VLOOKUP($A13,'Consolidate List'!$A$2:$P$1048576,5,FALSE)),", ",VLOOKUP($A13,'Consolidate List'!$A$2:$P$1048576,6,FALSE)),"") -> Brussel, Brussel | K13: =IFERROR(VLOOKUP($A13,'Consolidate List'!$A$2:$P$1048576,17,FALSE),"")
... A500: =IFERROR(Tableau1[[#This Row],[ID Unique]],"") | B500: =IFERROR(VLOOKUP($A500,'Consolidate List'!$A$2:$P$1048576,15,FALSE),"") | C500: =IFERROR(VLOOKUP($A500,'Consolidate List'!$A$2:$P$1048576,16,FALSE),"") | D500: =IFERROR(VLOOKUP($A500,'Consolidate List'!$A$2:$P$1048576,8,FALSE),"") | F500: =IFERROR(VLOOKUP($A500,'Consolidate List'!$A$2:$P$1048576,12,FALSE),"") | G500: =IFERROR(VLOOKUP($A500,'Consolidate List'!$A$2:$P$1048576,11,FALSE),"") | H500: =IFERROR(VLOOKUP($A500,'Consolidate List'!$A$2:$P$1048576,9,FALSE),"") | I500: =IFERROR(VLOOKUP($A500,'Consolidate List'!$A$2:$P$1048576,10,FALSE),"") | J500: =IFERROR(_xlfn.CONCAT((VLOOKUP($A500,'Consolidate List'!$A$2:$P$1048576,5,FALSE)),", ",VLOOKUP($A500,'Consolidate List'!$A$2:$P$1048576,6,FALSE)),"") | K500: =IFERROR(VLOOKUP($A500,'Consolidate List'!$A$2:$P$1048576,17,FALSE),"")

Sheet Feuil2
A3: Nombre de Type of DC | C3: Type of DC
A4: Zone | B4: Country | C4: 1 - Major | D4: 2 - Opportunistic | E4: Total général
A5: AME
B6: Brazil | D6: 4 | E6: 4
B7: Costa Rica | D7: 1 | E7: 1
B8: United States | C8: 2 | D8: 28 | E8: 30
A9: Total AME | C9: 2 | D9: 33 | E9: 35
A11: APAC
B12: Australia | C12: 1 | D12: 7 | E12: 8
B13: China | C13: 1 | D13: 9 | E13: 10
B14: India | D14: 3 | E14: 3
B15: Japan | D15: 6 | E15: 6
B16: Singapore | C16: 4 | D16: 1 | E16: 5
A17: Total APAC | C17: 6 | D17: 26 | E17: 32
A19: EMEA
B20: France | C20: 11 | D20: 8 | E20: 19
B21: Germany | C21: 1 | D21: 5 | E21: 6
B22: Italy | D22: 1 | E22: 1
B23: Ivory Coast | D23: 1 | E23: 1
B24: Maroc | D24: 1 | E24: 1
B25: Netherlands | C25: 2 | D25: 5 | E25: 7
B26: Norway | C26: 2 | E26: 2
B27: Poland | D27: 1 | E27: 1
B28: Russia | D28: 1 | E28: 1
B29: Senegal | D29: 1 | E29: 1
B30: South Africa | D30: 1 | E30: 1
B31: Spain | D31: 1 | E31: 1
B32: Switzerland | D32: 1 | E32: 1
B33: UAE | D33: 1 | E33: 1
B34: United Kingdom | D34: 6 | E34: 6
A35: Total EMEA | C35: 16 | D35: 34 | E35: 50
A37: Total général | C37: 24 | D37: 93 | E37: 117

Sheet Consolidate List
A1: ID Unique | B1: Zone | C1: Region | D1: Country | E1: Cluster City | F1: City Area | G1: Supplier | H1: Site Code Orange | I1: Address | J1: Datacenter name (supplier code) | K1: Type of DC | L1: Affichage DCMAP (O/N) | M1: DC Manager | N1: Latitude | O1: Longitude | P1: Plazza Proximity
A2: =UPPER(_xlfn.CONCAT(LEFT(Tableau1[[#This Row],[Supplier]],2),LEFT(Tableau1[[#This Row],[City Area]],2),LEFT(Tableau1[[#This Row],[Datacenter name (supplier code)]],4),LEFT(Tableau1[[#This Row],[Country]],2),RIGHT(Tableau1[[#This Row],[Datacenter name (supplier code)]],2))) -> CIBUBUE1ARE1 | B2: AME | C2: LAM | D2: Argentina | E2: Buenos Aires | F2: Buenos Aires | G2: Cirion Argentina | H2: BUEL01 | I2: Av. del Campo 1301, Buenos Aires, Argentine | J2: BUE1 | K2: 3 - Opportunistic not to promote | L2: =IF(OR(Tableau1[[#This Row],[Type of DC]]="1 - Major",Tableau1[[#This Row],[Type of DC]]="2 - Opportunistic",Tableau1[[#This Row],[Type of DC]]="6 - Catalog"),"OUI","NON") -> NON | M2: Arnaud GIRAUD | N2: -34.59002 | O2: -58.46698190000001
A3: =UPPER(_xlfn.CONCAT(LEFT(Tableau1[[#This Row],[Supplier]],2),LEFT(Tableau1[[#This Row],[City Area]],2),LEFT(Tableau1[[#This Row],[Datacenter name (supplier code)]],4),LEFT(Tableau1[[#This Row],[Country]],2),RIGHT(Tableau1[[#This Row],[Datacenter name (supplier code)]],2))) -> EQSYNORTAU01 | B3: APAC | C3: APAC | D3: Australia | E3: Sydney | F3: Sydney | G3: Equant | H3: SYDX01 | I3: Unit 8, 5 Talavera Road, Macquarie Park, NSW, 2113 | J3: North Ryde SYDX01 | K3: 5 - Closed | L3: =IF(OR(Tableau1[[#This Row],[Type of DC]]="1 - Major",Tableau1[[#This Row],[Type of DC]]="2 - Opportunistic",Tableau1[[#This Row],[Type of DC]]="6 - Catalog"),"OUI","NON") -> NON | M3: John YIP | N3: -33.7838685 | O3: 151.1317254
A4: =UPPER(_xlfn.CONCAT(LEFT(Tableau1[[#This Row],[Supplier]],2),LEFT(Tableau1[[#This Row],[City Area]],2),LEFT(Tableau1[[#This Row],[Datacenter name (supplier code)]],4),LEFT(Tableau1[[#This Row],[Country]],2),RIGHT(Tableau1[[#This Row],[Datacenter name (supplier code)]],2))) -> EQSASP4BRP4 | B4: AME | C4: LAM | D4: Brazil | E4: Sao Paulo | F4: Sao Paulo | G4: Equinix | H4: SAOI01 | I4: Av. Ceci, 1900 - Res. Tambore, Barueri - SP, 06460-120, Brésil | J4: SP4 | K4: 2 - Opportunistic | L4: =IF(OR(Tableau1[[#This Row],[Type of DC]]="1 - Major",Tableau1[[#This Row],[Type of DC]]="2 - Opportunistic",Tableau1[[#This Row],[Type of DC]]="6 - Catalog"),"OUI","NON") -> OUI | M4: Arnaud GIRAUD | N4: -23.4933594 | O4: -46.8094334 | P4: https://plazza.orange.com/docs/DOC-520558
A5: =UPPER(_xlfn.CONCAT(LEFT(Tableau1[[#This Row],[Supplier]],2),LEFT(Tableau1[[#This Row],[City Area]],2),LEFT(Tableau1[[#This Row],[Datacenter name (supplier code)]],4),LEFT(Tableau1[[#This Row],[Country]],2),RIGHT(Tableau1[[#This Row],[Datacenter name (supplier code)]],2))) -> EQRIRJ1BRJ1 | B5: AME | C5: LAM | D5: Brazil | E5: Rio de Janeiro | F5: Rio de Janeiro | G5: Equinix | H5: not found on GINI | I5: Rua Voluntários da Pátria 360 - Botafogo 22270-010 Rio de Janeiro | J5: RJ1 | K5: 2 - Opportunistic | L5: =IF(OR(Tableau1[[#This Row],[Type of DC]]="1 - Major",Tableau1[[#This Row],[Type of DC]]="2 - Opportunistic",Tableau1[[#This Row],[Type of DC]]="6 - Catalog"),"OUI","NON") -> OUI | M5: Arnaud GIRAUD | N5: -22.9547717 | O5: -43.1945909 | P5: https://plazza.orange.com/docs/DOC-520558
A6: =UPPER(_xlfn.CONCAT(LEFT(Tableau1[[#This Row],[Supplier]],2),LEFT(Tableau1[[#This Row],[City Area]],2),LEFT(Tableau1[[#This Row],[Datacenter name (supplier code)]],4),LEFT(Tableau1[[#This Row],[Country]],2),RIGHT(Tableau1[[#This Row],[Datacenter name (supplier code)]],2))) -> VOBEVDC-AU02 | B6: APAC | C6: APAC | D6: Australia | E6: Perth | F6: Bently | G6: Vocus | H6: not found on GINI | I6: Vocus VDC-PER02 Data Centre., 5 Watts Place, Bentley WA 6102, Australia. | J6: VDC-PER02 | K6: 3 - Opportunistic not to promote | L6: =IF(OR(Tableau1[[#This Row],[Type of DC]]="1 - Major",Tableau1[[#This Row],[Type of DC]]="2 - Opportunistic",Tableau1[[#This Row],[Type of DC]]="6 - Catalog"),"OUI","NON") -> NON | M6: John YIP | N6: -31.9962499 | O6: 115.8884299
A7: =UPPER(_xlfn.CONCAT(LEFT(Tableau1[[#This Row],[Supplier]],2),LEFT(Tableau1[[#This Row],[City Area]],2),LEFT(Tableau1[[#This Row],[Datacenter name (supplier code)]],4),LEFT(Tableau1[[#This Row],[Country]],2),RIGHT(Tableau1[[#This Row],[Datacenter name (supplier code)]],2))) -> EQSASP2BRP2 | B7: AME | C7: LAM | D7: Brazil | E7: Sao Paulo | F7: Sao Paulo | G7: Equinix | H7: SAOD04 | I7: Al. Araguaia 3641 - Tamboré Barueri - SP CEP: 06455-000 | J7: SP2 | K7: 2 - Opportunistic | L7: =IF(OR(Tableau1[[#This Row],[Type of DC]]="1 - Major",Tableau1[[#This Row],[Type of DC]]="2 - Opportunistic",Tableau1[[#This Row],[Type of DC]]="6 - Catalog"),"OUI","NON") -> OUI | M7: Arnaud GIRAUD | N7: -23.5031326 | O7: -46.8272798 | P7: https://plazza.orange.com/docs/DOC-520558
A8: =UPPER(_xlfn.CONCAT(LEFT(Tableau1[[#This Row],[Supplier]],2),LEFT(Tableau1[[#This Row],[City Area]],2),LEFT(Tableau1[[#This Row],[Datacenter name (supplier code)]],4),LEFT(Tableau1[[#This Row],[Country]],2),RIGHT(Tableau1[[#This Row],[Datacenter name (supplier code)]],2))) -> EQSASP3BRP3 | B8: AME | C8: LAM | D8: Brazil | E8: Sao Paulo | F8: Sao Paulo | G8: Equinix | H8: GRU01 | I8: Avenida Marcos Penteado de Ulhoa Rodrigues, 249 Santana de Parnaiba/SP CEP: 06543-001 Brazil | J8: SP3 | K8: 2 - Opportunistic | L8: =IF(OR(Tableau1[[#This Row],[Type of DC]]="1 - Major",Tableau1[[#This Row],[Type of DC]]="2 - Opportunistic",Tableau1[[#This Row],[Type of DC]]="6 - Catalog"),"OUI","NON") -> OUI | M8: Arnaud GIRAUD | N8: -23.4663344 | O8: -46.86328839999999 | P8: https://plazza.orange.com/docs/DOC-520558
A9: =UPPER(_xlfn.CONCAT(LEFT(Tableau1[[#This Row],[Supplier]],2),LEFT(Tableau1[[#This Row],[City Area]],2),LEFT(Tableau1[[#This Row],[Datacenter name (supplier code)]],4),LEFT(Tableau1[[#This Row],[Country]],2),RIGHT(Tableau1[[#This Row],[Datacenter name (supplier code)]],2))) -> ADSAADN COSE | B9: AME | C9: LAM | D9: Costa Rica | E9: San Jose | F9: San Jose | G9: ADN Datacenter | H9: SJOL01 | I9: ADN Datacenters, Zona Franca SARET Edificio B8 Alajuela Costa Rica | J9: ADN by UFINET - San Jose | K9: 2 - Opportunistic | L9: =IF(OR(Tableau1[[#This Row],[Type of DC]]="1 - Major",Tableau1[[#This Row],[Type of DC]]="2 - Opportunistic",Tableau1[[#This Row],[Type of DC]]="6 - Catalog"),"OUI","NON") -> OUI | M9: Arnaud GIRAUD | N9: 10.0004151 | O9: -84.1857912 | P9: To be done
A10: =UPPER(_xlfn.CONCAT(LEFT(Tableau1[[#This Row],[Supplier]],2),LEFT(Tableau1[[#This Row],[City Area]],2),LEFT(Tableau1[[#This Row],[Datacenter name (supplier code)]],4),LEFT(Tableau1[[#This Row],[Country]],2),RIGHT(Tableau1[[#This Row],[Datacenter name (supplier code)]],2))) -> CODADAL3UNL3 | B10: AME | C10: NAM | D10: United States | E10: Texas | F10: Dallas | G10: Cologix | H10: DALL02 | I10: 1950 North Stemmons Freeway, Suites 1039A & 2048, Dallas, Texas, United States of America, 75207 | J10: DAL3 | K10: 2 - Opportunistic | L10: =IF(OR(Tableau1[[#This Row],[Type of DC]]="1 - Major",Tableau1[[#This Row],[Type of DC]]="2 - Opportunistic",Tableau1[[#This Row],[Type of DC]]="6 - Catalog"),"OUI","NON") -> OUI | M10: Mark OLSZEWSKI | N10: 32.800748 | O10: -96.819412 | P10: To be done
A11: =UPPER(_xlfn.CONCAT(LEFT(Tableau1[[#This Row],[Supplier]],2),LEFT(Tableau1[[#This Row],[City Area]],2),LEFT(Tableau1[[#This Row],[Datacenter name (supplier code)]],4),LEFT(Tableau1[[#This Row],[Country]],2),RIGHT(Tableau1[[#This Row],[Datacenter name (supplier code)]],2))) -> COMOMTL7CAL7 | B11: AME | C11: NAM | D11: Canada | E11: Ontario | F11: Montreal | G11: Cologix | H11: n/a | I11: 1155 Blvd. Robert-Bourassa, Montreal, QC H3B 3A7 | J11: MTL7 | K11: 2 - Opportunistic | L11: =IF(OR(Tableau1[[#This Row],[Type of DC]]="1 - Major",Tableau1[[#This Row],[Type of DC]]="2 - Opportunistic",Tableau1[[#This Row],[Type of DC]]="6 - Catalog"),"OUI","NON") -> OUI | M11: Mark OLSZEWSKI
A12: =UPPER(_xlfn.CONCAT(LEFT(Tableau1[[#This Row],[Supplier]],2),LEFT(Tableau1[[#This Row],[City Area]],2),LEFT(Tableau1[[#This Row],[Datacenter name (supplier code)]],4),LEFT(Tableau1[[#This Row],[Country]],2),RIGHT(Tableau1[[#This Row],[Datacenter name (supplier code)]],2))) -> COTOTOR1CAR1 | B12: AME | C12: NAM | D12: Canada | E12: Ontario | F12: Toronto | G12: Cologix | H12: n/a | I12: 151 Front St. W, Toronto, ON M5J 2N1 | J12: TOR1 | K12: 2 - Opportunistic | L12: =IF(OR(Tableau1[[#This Row],[Type of DC]]="1 - Major",Tableau1[[#This Row],[Type of DC]]="2 - Opportunistic",Tableau1[[#This Row],[Type of DC]]="6 - Catalog"),"OUI","NON") -> OUI | M12: Mark OLSZEWSKI
A13: =UPPER(_xlfn.CONCAT(LEFT(Tableau1[[#This Row],[Supplier]],2),LEFT(Tableau1[[#This Row],[City Area]],2),LEFT(Tableau1[[#This Row],[Datacenter name (supplier code)]],4),LEFT(Tableau1[[#This Row],[Country]],2),RIGHT(Tableau1[[#This Row],[Datacenter name (supplier code)]],2))) -> MOBRSTUABEDC | B13: EMEA | C13: EMEA | D13: Belgium | E13: Brussel | F13: Brussel | G13: Mobistar | H13: BRUT03 | I13: Mobistar Datacenter Nossegem Leuvensesteenweg 641,1930 Zaventem, Belgium | J13: Stuart DC | K13: 3 - Opportunistic not to promote | L13: =IF(OR(Tableau1[[#This Row],[Type of DC]]="1 - Major",Tableau1[[#This Row],[Type of DC]]="2 - Opportunistic",Tableau1[[#This Row],[Type of DC]]="6 - Catalog"),"OUI","NON") -> NON | M13: Mohamed SAMIR | N13: 50.87765899999999 | O13: 4.5035326
A14: =UPPER(_xlfn.CONCAT(LEFT(Tableau1[[#This Row],[Supplier]],2),LEFT(Tableau1[[#This Row],[City Area]],2),LEFT(Tableau1[[#This Row],[Datacenter name (supplier code)]],4),LEFT(Tableau1[[#This Row],[Country]],2),RIGHT(Tableau1[[#This Row],[Datacenter name (supplier code)]],2))) -> EQATAT1UNT1 | B14: AME | C14: NAM | D14: United States | E14: Georgia | F14: Atlanta | G14: Equinix | H14: ATLL03 | I14: 180 Peachtree Street NW, 2nd and 6th Floors, Atlanta, Georgia, United States of America, 30303 | J14: AT1 | K14: 2 - Opportunistic | L14: =IF(OR(Tableau1[[#This Row],[Type of DC]]="1 - Major",Tableau1[[#This Row],[Type of DC]]="2 - Opportunistic",Tableau1[[#This Row],[Type of DC]]="6 - Catalog"),"OUI","NON") -> OUI | M14: Mark OLSZEWSKI | N14: 33.7585633 | O14: -84.3877746 | P14: https://plazza.orange.com/docs/DOC-759493
A15: =UPPER(_xlfn.CONCAT(LEFT(Tableau1[[#This Row],[Supplier]],2),LEFT(Tableau1[[#This Row],[City Area]],2),LEFT(Tableau1[[#This Row],[Datacenter name (supplier code)]],4),LEFT(Tableau1[[#This Row],[Country]],2),RIGHT(Tableau1[[#This Row],[Datacenter name (supplier code)]],2))) -> CISASAO1BRO1 | B15: AME | C15: LAM | D15: Brazil | E15: Sao Paulo | F15: Sao Paulo | G15: Cirion Brazil | H15: SAOL01 | I15: Av. Eid Mansur, 666 - Parque São Jorge, Cotia - SP, 06708-070, Brésil | J15: SAO1 | K15: 3 - Opportunistic not to promote | L15: =IF(OR(Tableau1[[#This Row],[Type of DC]]="1 - Major",Tableau1[[#This Row],[Type of DC]]="2 - Opportunistic",Tableau1[[#This Row],[Type of DC]]="6 - Catalog"),"OUI","NON") -> NON | M15: Arnaud GIRAUD | N15: -23.5979329 | O15: -46.848808
A16: =UPPER(_xlfn.CONCAT(LEFT(Tableau1[[#This Row],[Supplier]],2),LEFT(Tableau1[[#This Row],[City Area]],2),LEFT(Tableau1[[#This Row],[Datacenter name (supplier code)]],4),LEFT(Tableau1[[#This Row],[Country]],2),RIGHT(Tableau1[[#This Row],[Datacenter name (supplier code)]],2))) -> EMRIEMBRBRIO | B16: AME | C16: LAM | D16: Brazil | E16: Rio de Janeiro | F16: Rio de Janeiro | G16: Embratel | H16: RIOL02 | I16: 119 Rua Senador Pompeu, Rio de Janeiro, 20221-291, Brazil | J16: Embratel - Rio | K16: 3 - Opportunistic not to promote | L16: =IF(OR(Tableau1[[#This Row],[Type of DC]]="1 - Major",Tableau1[[#This Row],[Type of DC]]="2 - Opportunistic",Tableau1[[#This Row],[Type of DC]]="6 - Catalog"),"OUI","NON") -> NON | M16: Arnaud GIRAUD | N16: -22.9006419 | O16: -43.188142
A17: =UPPER(_xlfn.CONCAT(LEFT(Tableau1[[#This Row],[Supplier]],2),LEFT(Tableau1[[#This Row],[City Area]],2),LEFT(Tableau1[[#This Row],[Datacenter name (supplier code)]],4),LEFT(Tableau1[[#This Row],[Country]],2),RIGHT(Tableau1[[#This Row],[Datacenter name (supplier code)]],2))) -> EQCHCH1UNH1 | B17: AME | C17: NAM | D17: United States | E17: Illinois | F17: Chicago | G17: Equinix | H17: CHIL02 | I17: 350 E Cermak Rd, 6th Floor, Chicago, Illinois, United States of America, 60616 | J17: CH1 | K17: 2 - Opportunistic | L17: =IF(OR(Tableau1[[#This Row],[Type of DC]]="1 - Major",Tableau1[[#This Row],[Type of DC]]="2 - Opportunistic",Tableau1[[#This Row],[Type of DC]]="6 - Catalog"),"OUI","NON") -> OUI | M17: Mark OLSZEWSKI | N17: 41.8531135 | O17: -87.6183281 | P17: https://plazza.orange.com/docs/DOC-759493
A18: =UPPER(_xlfn.CONCAT(LEFT(Tableau1[[#This Row],[Supplier]],2),LEFT(Tableau1[[#This Row],[City Area]],2),LEFT(Tableau1[[#This Row],[Datacenter name (supplier code)]],4),LEFT(Tableau1[[#This Row],[Country]],2),RIGHT(Tableau1[[#This Row],[Datacenter name (supplier code)]],2))) -> SYSASYDEBRLO | B18: AME | C18: LAM | D18: Brazil | E18: Sao Paulo | F18: Sao Paulo | G18: Sydel | H18: not found on GINI | I18: Av. Adolfo Pinheiro, 1.000, Cj 51/53 • Alto da Boa Vista • CEP 04734-002 • São Paulo - SP | J18: Sydel Sao paulo | K18: 5 - Closed | L18: =IF(OR(Tableau1[[#This Row],[Type of DC]]="1 - Major",Tableau1[[#This Row],[Type of DC]]="2 - Opportunistic",Tableau1[[#This Row],[Type of DC]]="6 - Catalog"),"OUI","NON") -> NON | M18: Arnaud GIRAUD | N18: -23.6522787 | O18: -46.705799
A19: =UPPER(_xlfn.CONCAT(LEFT(Tableau1[[#This Row],[Supplier]],2),LEFT(Tableau1[[#This Row],[City Area]],2),LEFT(Tableau1[[#This Row],[Datacenter name (supplier code)]],4),LEFT(Tableau1[[#This Row],[Country]],2),RIGHT(Tableau1[[#This Row],[Datacenter name (supplier code)]],2))) -> EQCHCH2UNH2 | B19: AME | C19: NAM | D19: United States | E19: Illinois | F19: Chicago | G19: Equinix | H19: CHID03 | I19: 350 E Cermak Rd, 5th Floor, Chicago, Illinois, United States of America, 60616 | J19: CH2 | K19: 2 - Opportunistic | L19: =IF(OR(Tableau1[[#This Row],[Type of DC]]="1 - Major",Tableau1[[#This Row],[Type of DC]]="2 - Opportunistic",Tableau1[[#This Row],[Type of DC]]="6 - Catalog"),"OUI","NON") -> OUI | M19: Mark OLSZEWSKI | N19: 41.8531135 | O19: -87.6183281 | P19: https://plazza.orange.com/docs/DOC-759493
A20: =UPPER(_xlfn.CONCAT(LEFT(Tableau1[[#This Row],[Supplier]],2),LEFT(Tableau1[[#This Row],[City Area]],2),LEFT(Tableau1[[#This Row],[Datacenter name (supplier code)]],4),LEFT(Tableau1[[#This Row],[Country]],2),RIGHT(Tableau1[[#This Row],[Datacenter name (supplier code)]],2))) -> TESATELEBRLO | B20: AME | C20: LAM | D20: Brazil | E20: Sao Paulo | F20: Sao Paulo | G20: Telefonica | H20: SAOD01 / SAOD02 | I20: The Tamboré II Data Center / Alameda Araguacema, 187 - Barueri - SP / CEP 0646 / SP SÃO PAULO / BRAZIL | J20: Telefonica Sao Paulo | K20: 5 - Closed | L20: =IF(OR(Tableau1[[#This Row],[Type of DC]]="1 - Major",Tableau1[[#This Row],[Type of DC]]="2 - Opportunistic",Tableau1[[#This Row],[Type of DC]]="6 - Catalog"),"OUI","NON") -> NON | M20: Arnaud GIRAUD | N20: -23.5019755 | O20: -46.8251239
A21: =UPPER(_xlfn.CONCAT(LEFT(Tableau1[[#This Row],[Supplier]],2),LEFT(Tableau1[[#This Row],[City Area]],2),LEFT(Tableau1[[#This Row],[Datacenter name (supplier code)]],4),LEFT(Tableau1[[#This Row],[Country]],2),RIGHT(Tableau1[[#This Row],[Datacenter name (supplier code)]],2))) -> EQCHCH4UNH4 | B21: AME | C21: NAM | D21: United States | E21: Illinois | F21: Chicago | G21: Equinix | H21: CHIF03 | I21: 350 E Cermak Rd, 8th Floor, Chicago, Illinois, United States of America, 60616 | J21: CH4 | K21: 2 - Opportunistic | L21: =IF(OR(Tableau1[[#This Row],[Type of DC]]="1 - Major",Tableau1[[#This Row],[Type of DC]]="2 - Opportunistic",Tableau1[[#This Row],[Type of DC]]="6 - Catalog"),"OUI","NON") -> OUI | M21: Mark OLSZEWSKI | N21: 41.8531135 | O21: -87.6183281 | P21: https://plazza.orange.com/docs/DOC-759493
A22: =UPPER(_xlfn.CONCAT(LEFT(Tableau1[[#This Row],[Supplier]],2),LEFT(Tableau1[[#This Row],[City Area]],2),LEFT(Tableau1[[#This Row],[Datacenter name (supplier code)]],4),LEFT(Tableau1[[#This Row],[Country]],2),RIGHT(Tableau1[[#This Row],[Datacenter name (supplier code)]],2))) -> IISAIIA CHGO | B22: AME | C22: LAM | D22: Chile | E22: Santiago | F22: Santiago | G22: IIA | H22: SCLC02 | I22: Porvenir 245, Santiago | J22: IIA - Santiago | K22: 3 - Opportunistic not to promote | L22: =IF(OR(Tableau1[[#This Row],[Type of DC]]="1 - Major",Tableau1[[#This Row],[Type of DC]]="2 - Opportunistic",Tableau1[[#This Row],[Type of DC]]="6 - Catalog"),"OUI","NON") -> NON | M22: Arnaud GIRAUD | N22: -33.4549116 | O22: -70.632856
A23: =UPPER(_xlfn.CONCAT(LEFT(Tableau1[[#This Row],[Supplier]],2),LEFT(Tableau1[[#This Row],[City Area]],2),LEFT(Tableau1[[#This Row],[Datacenter name (supplier code)]],4),LEFT(Tableau1[[#This Row],[Country]],2),RIGHT(Tableau1[[#This Row],[Datacenter name (supplier code)]],2))) -> EQCUCU2UNU2 | B23: AME | C23: NAM | D23: United States | E23: Virginia | F23: Culpeper | G23: Equinix | H23: not found on GINI | I23: 18155 Technology Drive, Building B, Culpeper, VA, United States of America, 22701 | J23: CU2 | K23: 2 - Opportunistic | L23: =IF(OR(Tableau1[[#This Row],[Type of DC]]="1 - Major",Tableau1[[#This Row],[Type of DC]]="2 - Opportunistic",Tableau1[[#This Row],[Type of DC]]="6 - Catalog"),"OUI","NON") -> OUI | M23: Mark OLSZEWSKI | N23: 38.4551336 | O23: -77.9780767 | P23: https://plazza.orange.com/docs/DOC-759493
A24: =UPPER(_xlfn.CONCAT(LEFT(Tableau1[[#This Row],[Supplier]],2),LEFT(Tableau1[[#This Row],[City Area]],2),LEFT(Tableau1[[#This Row],[Datacenter name (supplier code)]],4),LEFT(Tableau1[[#This Row],[Country]],2),RIGHT(Tableau1[[#This Row],[Datacenter name (supplier code)]],2))) -> DRBEDR. CHNG | B24: APAC | C24: APAC | D24: China | E24: Beijing | F24: Beijing | G24: Dr. Peng | H24: not found on GINI | I24: No. 9 Jiuxianqiao North Road, Chaoyang District | J24: Dr. Peng | K24: 5 - Closed | L24: =IF(OR(Tableau1[[#This Row],[Type of DC]]="1 - Major",Tableau1[[#This Row],[Type of DC]]="2 - Opportunistic",Tableau1[[#This Row],[Type of DC]]="6 - Catalog"),"OUI","NON") -> NON | M24: Raymond CHEE | N24: 39.98794 | O24: 116.5
A25: =UPPER(_xlfn.CONCAT(LEFT(Tableau1[[#This Row],[Supplier]],2),LEFT(Tableau1[[#This Row],[City Area]],2),LEFT(Tableau1[[#This Row],[Datacenter name (supplier code)]],4),LEFT(Tableau1[[#This Row],[Country]],2),RIGHT(Tableau1[[#This Row],[Datacenter name (supplier code)]],2))) -> EQDADA3UNA3 | B25: AME | C25: NAM | D25: United States | E25: Texas | F25: Dallas | G25: Equinix | H25: not found on GINI | I25: 1950 North Stemmons Freeway, Dallas, Texas, United States of America, 75207 | J25: DA3 | K25: 2 - Opportunistic | L25: =IF(OR(Tableau1[[#This Row],[Type of DC]]="1 - Major",Tableau1[[#This Row],[Type of DC]]="2 - Opportunistic",Tableau1[[#This Row],[Type of DC]]="6 - Catalog"),"OUI","NON") -> OUI | M25: Mark OLSZEWSKI | N25: 32.8007033 | O25: -96.8191899 | P25: https://plazza.orange.com/docs/DOC-759493
A26: =UPPER(_xlfn.CONCAT(LEFT(Tableau1[[#This Row],[Supplier]],2),LEFT(Tableau1[[#This Row],[City Area]],2),LEFT(Tableau1[[#This Row],[Datacenter name (supplier code)]],4),LEFT(Tableau1[[#This Row],[Country]],2),RIGHT(Tableau1[[#This Row],[Datacenter name (supplier code)]],2))) -> NTTANTT CHPO | B26: APAC | C26: APAC | D26: China | E26: Hong Kong | F26: Tai Po | G26: NTT | H26: HKGD02 | I26: 2 Dai Hei Street, Tai Po Industrial Park, Tai Po, N.T., Hong Kong | J26: NTT Tai Po | K26: 5 - Closed | L26: =IF(OR(Tableau1[[#This Row],[Type of DC]]="1 - Major",Tableau1[[#This Row],[Type of DC]]="2 - Opportunistic",Tableau1[[#This Row],[Type of DC]]="6 - Catalog"),"OUI","NON") -> NON | M26: Raymond CHEE | N26: 22.453481 | O26: 114.1871295
A27: =UPPER(_xlfn.CONCAT(LEFT(Tableau1[[#This Row],[Supplier]],2),LEFT(Tableau1[[#This Row],[City Area]],2),LEFT(Tableau1[[#This Row],[Datacenter name (supplier code)]],4),LEFT(Tableau1[[#This Row],[Country]],2),RIGHT(Tableau1[[#This Row],[Datacenter name (supplier code)]],2))) -> EQASDC10UN10 | B27: AME | C27: NAM | D27: United States | E27: Virginia | F27: Ashburn | G27: Equinix | H27: n/a | I27: 21551 Beaumeade Circle, Ashburn, VA 20147 | J27: DC10 | K27: 2 - Opportunistic | L27: =IF(OR(Tableau1[[#This Row],[Type of DC]]="1 - Major",Tableau1[[#This Row],[Type of DC]]="2 - Opportunistic",Tableau1[[#This Row],[Type of DC]]="6 - Catalog"),"OUI","NON") -> OUI | M27: Mark OLSZEWSKI
A28: =UPPER(_xlfn.CONCAT(LEFT(Tableau1[[#This Row],[Supplier]],2),LEFT(Tableau1[[#This Row],[City Area]],2),LEFT(Tableau1[[#This Row],[Datacenter name (supplier code)]],4),LEFT(Tableau1[[#This Row],[Country]],2),RIGHT(Tableau1[[#This Row],[Datacenter name (supplier code)]],2))) -> EQASDC11UN11 | B28: AME | C28: NAM | D28: United States | E28: Virginia | F28: Ashburn | G28: Equinix | H28: IADF02 | I28: 21721 Filigree Court, Ashburn, VA 20147 | J28: DC11 | K28: 2 - Opportunistic | L28: =IF(OR(Tableau1[[#This Row],[Type of DC]]="1 - Major",Tableau1[[#This Row],[Type of DC]]="2 - Opportunistic",Tableau1[[#This Row],[Type of DC]]="6 - Catalog"),"OUI","NON") -> OUI | M28: Mark OLSZEWSKI | N28: 39.0152031 | O28: -77.4594652 | P28: https://plazza.orange.com/docs/DOC-759493
A29: =UPPER(_xlfn.CONCAT(LEFT(Tableau1[[#This Row],[Supplier]],2),LEFT(Tableau1[[#This Row],[City Area]],2),LEFT(Tableau1[[#This Row],[Datacenter name (supplier code)]],4),LEFT(Tableau1[[#This Row],[Country]],2),RIGHT(Tableau1[[#This Row],[Datacenter name (supplier code)]],2))) -> EQASDC13UN13 | B29: AME | C29: NAM | D29: United States | E29: Virginia | F29: Ashburn | G29: Equinix | H29: not found on GINI | I29: 21830 Uunet Way, Ashburn, Virginia, United States of America, 20147 | J29: DC13 | K29: 2 - Opportunistic | L29: =IF(OR(Tableau1[[#This Row],[Type of DC]]="1 - Major",Tableau1[[#This Row],[Type of DC]]="2 - Opportunistic",Tableau1[[#This Row],[Type of DC]]="6 - Catalog"),"OUI","NON") -> OUI | M29: Mark OLSZEWSKI | N29: 39.0124932 | O29: -77.4753692 | P29: https://plazza.orange.com/docs/DOC-759493
A30: =UPPER(_xlfn.CONCAT(LEFT(Tableau1[[#This Row],[Supplier]],2),LEFT(Tableau1[[#This Row],[City Area]],2),LEFT(Tableau1[[#This Row],[Datacenter name (supplier code)]],4),LEFT(Tableau1[[#This Row],[Country]],2),RIGHT(Tableau1[[#This Row],[Datacenter name (supplier code)]],2))) -> EQASDC21UN21 | B30: AME | C30: NAM | D30: United States | E30: Virginia | F30: Ashburn | G30: Equinix | H30: not found on GINI | I30: 22175 Beaumeade Circle, Ashburn, Virginia, United States of America, 20147 | J30: DC21 | K30: 2 - Opportunistic | L30: =IF(OR(Tableau1[[#This Row],[Type of DC]]="1 - Major",Tableau1[[#This Row],[Type of DC]]="2 - Opportunistic",Tableau1[[#This Row],[Type of DC]]="6 - Catalog"),"OUI","NON") -> OUI | M30: Mark OLSZEWSKI | N30: 39.0119765 | O30: -77.45414099999999 | P30: https://plazza.orange.com/docs/DOC-759493
A31: =UPPER(_xlfn.CONCAT(LEFT(Tableau1[[#This Row],[Supplier]],2),LEFT(Tableau1[[#This Row],[City Area]],2),LEFT(Tableau1[[#This Row],[Datacenter name (supplier code)]],4),LEFT(Tableau1[[#This Row],[Country]],2),RIGHT(Tableau1[[#This Row],[Datacenter name (supplier code)]],2))) -> EQASDC3UNC3 | B31: AME | C31: NAM | D31: United States | E31: Virginia | F31: Ashburn | G31: Equinix | H31: not found on GINI | I31: 44470 Chilum Place, 20147, Ashburn | J31: DC3 | K31: 2 - Opportunistic | L31: =IF(OR(Tableau1[[#This Row],[Type of DC]]="1 - Major",Tableau1[[#This Row],[Type of DC]]="2 - Opportunistic",Tableau1[[#This Row],[Type of DC]]="6 - Catalog"),"OUI","NON") -> OUI | M31: Mark OLSZEWSKI | N31: 39.0221038 | O31: -77.460696 | P31: https://plazza.orange.com/docs/DOC-759493
A32: =UPPER(_xlfn.CONCAT(LEFT(Tableau1[[#This Row],[Supplier]],2),LEFT(Tableau1[[#This Row],[City Area]],2),LEFT(Tableau1[[#This Row],[Datacenter name (supplier code)]],4),LEFT(Tableau1[[#This Row],[Country]],2),RIGHT(Tableau1[[#This Row],[Datacenter name (supplier code)]],2))) -> NTKWNTT CHNG | B32: APAC | C32: APAC | D32: China | E32: Hong Kong | F32: Kwai Chung | G32: NTT | H32: HKGD01 | I32: 15/F, Tower 2, Ever Gain Plaza, 88 Container Port Road, Kwai Chung, N.T., Hong Kong | J32: NTT Kwai Chung | K32: 5 - Closed | L32: =IF(OR(Tableau1[[#This Row],[Type of DC]]="1 - Major",Tableau1[[#This Row],[Type of DC]]="2 - Opportunistic",Tableau1[[#This Row],[Type of DC]]="6 - Catalog"),"OUI","NON") -> NON | M32: Raymond CHEE | N32: 22.3529122 | O32: 114.1245238
A33: =UPPER(_xlfn.CONCAT(LEFT(Tableau1[[#This Row],[Supplier]],2),LEFT(Tableau1[[#This Row],[City Area]],2),LEFT(Tableau1[[#This Row],[Datacenter name (supplier code)]],4),LEFT(Tableau1[[#This Row],[Country]],2),RIGHT(Tableau1[[#This Row],[Datacenter name (supplier code)]],2))) -> EQASDC4UNC4 | B33: AME | C33: NAM | D33: United States | E33: Virginia | F33: Ashburn | G33: Equinix | H33: IADD03 | I33: 21691 Filigree Court, Ashburn, Virginia, United States of America, 20147 | J33: DC4 | K33: 2 - Opportunistic | L33: =IF(OR(Tableau1[[#This Row],[Type of DC]]="1 - Major",Tableau1[[#This Row],[Type of DC]]="2 - Opportunistic",Tableau1[[#This Row],[Type of DC]]="6 - Catalog"),"OUI","NON") -> OUI | M33: Mark OLSZEWSKI | N33: 39.0164848 | O33: -77.4619615 | P33: https://plazza.orange.com/docs/DOC-759493
A34: =UPPER(_xlfn.CONCAT(LEFT(Tableau1[[#This Row],[Supplier]],2),LEFT(Tableau1[[#This Row],[City Area]],2),LEFT(Tableau1[[#This Row],[Datacenter name (supplier code)]],4),LEFT(Tableau1[[#This Row],[Country]],2),RIGHT(Tableau1[[#This Row],[Datacenter name (supplier code)]],2))) -> EQDEDE1UNE1 | B34: AME | C34: NAM | D34: United States | E34: Colorado | F34: Denver | G34: Equinix | H34: not found on GINI | I34: 9706 East Easter Avenue Suite 160 Englewood, CO 80112 | J34: DE1 | K34: 2 - Opportunistic | L34: =IF(OR(Tableau1[[#This Row],[Type of DC]]="1 - Major",Tableau1[[#This Row],[Type of DC]]="2 - Opportunistic",Tableau1[[#This Row],[Type of DC]]="6 - Catalog"),"OUI","NON") -> OUI | M34: Mark OLSZEWSKI | N34: 39.5873917 | O34: -104.8763163 | P34: https://plazza.orange.com/docs/DOC-759493
A35: =UPPER(_xlfn.CONCAT(LEFT(Tableau1[[#This Row],[Supplier]],2),LEFT(Tableau1[[#This Row],[City Area]],2),LEFT(Tableau1[[#This Row],[Datacenter name (supplier code)]],4),LEFT(Tableau1[[#This Row],[Country]],2),RIGHT(Tableau1[[#This Row],[Datacenter name (supplier code)]],2))) -> EQDEDE2UNE2 | B35: AME | C35: NAM | D35: United States | E35: Colorado | F35: Denver | G35: Equinix | H35: n/a | I35: 335 Inverness Drive South, Englewood, CO 80112 | J35: DE2 | K35: 2 - Opportunistic | L35: =IF(OR(Tableau1[[#This Row],[Type of DC]]="1 - Major",Tableau1[[#This Row],[Type of DC]]="2 - Opportunistic",Tableau1[[#This Row],[Type of DC]]="6 - Catalog"),"OUI","NON") -> OUI | M35: Mark OLSZEWSKI
A36: =UPPER(_xlfn.CONCAT(LEFT(Tableau1[[#This Row],[Supplier]],2),LEFT(Tableau1[[#This Row],[City Area]],2),LEFT(Tableau1[[#This Row],[Datacenter name (supplier code)]],4),LEFT(Tableau1[[#This Row],[Country]],2),RIGHT(Tableau1[[#This Row],[Datacenter name (supplier code)]],2))) -> EQNENY1UNY1 | B36: AME | C36: NAM | D36: United States | E36: New Jersey | F36: Newark | G36: Equinix | H36: EWRR01 | I36: 165 Halsey St, 8th Floor, Newark, New Jersey, United States of America, 07102 | J36: NY1 | K36: 2 - Opportunistic | L36: =IF(OR(Tableau1[[#This Row],[Type of DC]]="1 - Major",Tableau1[[#This Row],[Type of DC]]="2 - Opportunistic",Tableau1[[#This Row],[Type of DC]]="6 - Catalog"),"OUI","NON") -> OUI | M36: Mark OLSZEWSKI | N36: 40.7368442 | O36: -74.17340229999999 | P36: https://plazza.orange.com/docs/DOC-759493
A37: =UPPER(_xlfn.CONCAT(LEFT(Tableau1[[#This Row],[Supplier]],2),LEFT(Tableau1[[#This Row],[City Area]],2),LEFT(Tableau1[[#This Row],[Datacenter name (supplier code)]],4),LEFT(Tableau1[[#This Row],[Country]],2),RIGHT(Tableau1[[#This Row],[Datacenter name (supplier code)]],2))) -> EQSENY2UNY2 | B37: AME | C37: NAM | D37: United States | E37: New Jersey | F37: Secaucus | G37: Equinix | H37: EWRL02 | I37: 275 Hartz Way, Secaucus, New Jersey, United States of America, 07094 | J37: NY2 | K37: 2 - Opportunistic | L37: =IF(OR(Tableau1[[#This Row],[Type of DC]]="1 - Major",Tableau1[[#This Row],[Type of DC]]="2 - Opportunistic",Tableau1[[#This Row],[Type of DC]]="6 - Catalog"),"OUI","NON") -> OUI | M37: Mark OLSZEWSKI | N37: 40.7778177 | O37: -74.07590859999999 | P37: https://plazza.orange.com/docs/DOC-759493
A38: =UPPER(_xlfn.CONCAT(LEFT(Tableau1[[#This Row],[Supplier]],2),LEFT(Tableau1[[#This Row],[City Area]],2),LEFT(Tableau1[[#This Row],[Datacenter name (supplier code)]],4),LEFT(Tableau1[[#This Row],[Country]],2),RIGHT(Tableau1[[#This Row],[Datacenter name (supplier code)]],2))) -> EQSENY5UNY5 | B38: AME | C38: NAM | D38: United States | E38: New Jersey | F38: Secaucus | G38: Equinix | H38: to be determined with GINI | I38: 800 Secaucus Rd, Secaucus, New Jersey, United States of America, 07094 | J38: NY5 | K38: 2 - Opportunistic | L38: =IF(OR(Tableau1[[#This Row],[Type of DC]]="1 - Major",Tableau1[[#This Row],[Type of DC]]="2 - Opportunistic",Tableau1[[#This Row],[Type of DC]]="6 - Catalog"),"OUI","NON") -> OUI | M38: Mark OLSZEWSKI | N38: 40.7785344 | O38: -74.0722373 | P38: https://plazza.orange.com/docs/DOC-759493
A39: =UPPER(_xlfn.CONCAT(LEFT(Tableau1[[#This Row],[Supplier]],2),LEFT(Tableau1[[#This Row],[City Area]],2),LEFT(Tableau1[[#This Row],[Datacenter name (supplier code)]],4),LEFT(Tableau1[[#This Row],[Country]],2),RIGHT(Tableau1[[#This Row],[Datacenter name (supplier code)]],2))) -> EQNEEQUAFR01 | B39: EMEA | C39: EMEA | D39: France | E39: Paris | F39: Neuilly | G39: Equant | H39: PART01 | I39: 112 Avenue Charles de Gaulle, 92522 Neuilly/Seine | J39: Equant PART01 | K39: 5 - Closed | L39: =IF(OR(Tableau1[[#This Row],[Type of DC]]="1 - Major",Tableau1[[#This Row],[Type of DC]]="2 - Opportunistic",Tableau1[[#This Row],[Type of DC]]="6 - Catalog"),"OUI","NON") -> NON | M39: Samy TAHIRI | N39: 48.8826709 | O39: 2.268323
A40: =UPPER(_xlfn.CONCAT(LEFT(Tableau1[[#This Row],[Supplier]],2),LEFT(Tableau1[[#This Row],[City Area]],2),LEFT(Tableau1[[#This Row],[Datacenter name (supplier code)]],4),LEFT(Tableau1[[#This Row],[Country]],2),RIGHT(Tableau1[[#This Row],[Datacenter name (supplier code)]],2))) -> ORNANANTFRIF | B40: EMEA | C40: EMEA | D40: France | E40: Paris | F40: Nanterre | G40: Orange France | H40: PARH02 | I40: 24, boulevard Jules Mansard 92000 NANTERRE. | J40: Nanterre - DIF | K40: 5 - Closed | L40: =IF(OR(Tableau1[[#This Row],[Type of DC]]="1 - Major",Tableau1[[#This Row],[Type of DC]]="2 - Opportunistic",Tableau1[[#This Row],[Type of DC]]="6 - Catalog"),"OUI","NON") -> NON | M40: Samy TAHIRI | N40: 48.8992225 | O40: 2.2111
...

Sheet Sheet1
A2: 1 - Major
A3: 2 - Opportunistic
A4: 3 - Opportunistic not to promote
A5: 4 - Frozen
A6: 5 - Closed

Sheet Liste source - OLD
A1: Region | B1: Country | C1: Cluster City | D1: City Area | E1: Supplier | F1: Site Code Orange | G1: Address | H1: Datacenter name (supplier code) | I1: Type of DC | J1: Classification Comment | K1: Existing DRP / Comment | L1: Facilities Site Owned by | M1: OCB contact ( supplier management, finances and capacity planning) | N1: DIF/FOIS contact (site manager) | O1: Proximity service contacts | P1: UHP / Comments | Q1: 24x7 Access security | R1: Customer top 18 | S1: m2 | T1: Audits & Certifications (to be requested via DC Plazza or Burgundy - see certification sheet) | U1: Infrastructure Datacenter Class | V1: Closed Orange Connectivity (km) | W1: OBS footprint | X1: Local Vendor/Supplier for cabling (IMPLE responsibility) | Y1: Local sourcing contact
A2: EMEA | B2: France | C2: Paris | D2: Nanterre | E2: Orange France | F2: PARH02 | G2: 24, boulevard Jules Mansard 92000 NANTERRE. | H2: Nanterre - DIF | I2: 5 - Closed | J2: Closure December 2016 | K2: No | L2: DIF | M2: Olivier Coroller Office +33 2 23 06 44 62 Mobile +33 6 71 92 65 97 olivier.coroller@orange.com | N2: PERES Frédéric DTSI/DIF +33 1 58 94 70 40 +33 6 74 41 88 66 | O2: Thierry Le Dorven resp. Conduite d'activité +33 1 55 22 12 22 | P2: Yes Link | Q2: contact:0 810 810 865 nanterre.dosidc@orange.com | R2: Carrefour TEREOS RIO TINTO LTD Equant IT&S | S2: 1500 | T2: - | U2: TIER III | V2: 0
A3: EMEA | B3: France | C3: Rennes | D3: Cesson Sevigne | E3: Orange France | F3: RNSH01 | G3: Equant, 9 rue du chene Germain, Cesson Sevigne 35512 | H3: Cesson - DIF | I3: 4 - Frozen | J3: Closure 2020 | K3: Yes Rueil (GDF) Oak-Hill (SGS) | L3: DIF | M3: Olivier Coroller Office +33 2 23 06 44 62 Mobile +33 6 71 92 65 97 olivier.coroller@orange.com | N3: PERES Frédéric DTSI/DIF +33 1 58 94 70 40 +33 6 74 41 88 66 | O3: Thierry Le Dorven resp. Conduite d'activité +33 1 55 22 12 22 | P3: Yes Link | Q3: reception: 02 23 28 66 92 rennes.dosidc@orange.com | R3: ENGIE OBS IT OCB PROD (clients externes) Eng Eq INFRA/OCB Eng Eq SECURITY Eng Eq MESSAGING Eng Eq CCS Eng Eq SUP Eng Eq Atlas | S3: 12 salles TIER III 2 797 m² (0.9 kW/m²) Greater than 99.99 % service availability | T3: ISAE 3402 - ISO 14001 | U3: TIER III | V3: 0
A4: EMEA | B4: France | C4: Paris | D4: Chevilly Larue | E4: Orange France | F4: PARH04 | G4: 72-74 av. De la Republique- 94550 Chevilly-Larue | H4: Chevilly - DIF | I4: 1 - Major | K4: Yes KDDI (LVMH) Rueil (multiple customers - synchronous mode available)) Normandie (ready) | L4: DIF | M4: Olivier Coroller Office +33 2 23 06 44 62 Mobile +33 6 71 92 65 97 olivier.coroller@orange.com | N4: PERES Frédéric DTSI/DIF +33 1 58 94 70 40 +33 6 74 41 88 66 | O4: Thierry Le Dorven resp. Conduite d'activité +33 1 55 22 12 22 | P4: Yes Link | Q4: security guard:01 45 60 95 99 chevilly.dosidc@orange.com 01 58 94 53 50 06 75 39 26 62 | R4: OAB ENGIE Flexible Exchange SI2M FCE LVMH Sagem-Communication SCOF AlloBizz TEREOS | S4: 3 rooms TIER III+ 1 550 m² (1kW /m²) Greater than 99.99 % service availability | T4: ISAE 3402 - ISO 14001 | U4: TIER III+ | V4: 0 | W4: 654
A5: EMEA | B5: France | C5: Paris | D5: Rueil-Malmaison | E5: Orange France | F5: QEVH01 | G5: 90 rue Pierre Brossolette 92500 Rueil Malmaison | H5: Rueil - DIF | I5: 1 - Major | K5: Yes Chevilly (multiple customers - synchronous mode available) Normandie (ready) | L5: DIF | M5: Olivier Coroller Office +33 2 23 06 44 62 Mobile +33 6 71 92 65 97 olivier.coroller@orange.com | N5: PERES Frédéric DTSI/DIF +33 1 58 94 70 40 +33 6 74 41 88 66 | O5: Thierry Le Dorven resp. Conduite d'activité +33 1 55 22 12 22 | P5: Yes Link | Q5: contact : 0 810 810 865 01 41 20 51 77 nanterre.dosidc@orange.com | R5: ENGIE SI2M Néoclès Cloudwatt TEREOS SCOF FCP V1 LVMH TMF Group Flexible Exchange | S5: 6 rooms TIER III+ 2 000 m² (1kW /m²) Greater than 99.99 % service availability | T5: ISAE 3402 - ISO 14001 | U5: TIER III+ | V5: 0 | W5: 650
A6: EMEA | B6: France | C6: Normandie | D6: Val de Reuil | E6: Orange France | F6: BVA07 | G6: Data Center Normandie 1 voie de l’orée (7 voie de l'Orée for equipment shipment) 27100 Val de Reuil. | H6: Normandie - DIF | I6: 1 - Major | K6: Yes Rueil (ready) Chevilly (ready) | L6: DIF | M6: Olivier Coroller Office +33 2 23 06 44 62 Mobile +33 6 71 92 65 97 olivier.coroller@orange.com | N6: PERES Frédéric DTSI/DIF +33 1 58 94 70 40 +33 6 74 41 88 66 | O6: Thierry Le Dorven resp. Conduite d'activité +33 1 55 22 12 22 | P6: Yes | Q6: contact:02 32 09 26 26 dei.dcn@orange.com Proximity Contact Nicolas Pagès : 0672079558 Contact logistic (equipment shipment) Xavier Cavelier : 0630444245 | R6: Cloudwatt OAB OBOS CGI Unified Defense TMF Group Spie Batignolles OINIS Diffusion Plus B2G3M | S6: >> 5,200 m2 of hosting out of a total surface area of 18,000 m2 >> 4 computer rooms, >> 6 POD OCB in each room >> 24 to 30 bays per POD >> Use of free cooling more than 80% of the time >> Greater than 99.995% service availability | T6: ISAE 3402 - ISO 14001 | U6: TIER IV | V6: 0 | W6: 462
A7: EMEA | B7: France | C7: Paris | D7: Neuilly | E7: Equant | F7: PART01 | G7: 112 Avenue Charles de Gaulle, 92522 Neuilly/Seine | H7: Equant PART01 | I7: 5 - Closed | J7: Closure 2018 DC 2016 | K7: No | L7: FOIS | M7: David Taieb Office : +33 1 40 91 36 39 Mobile : +33 6 81 87 76 63 david.taieb@orange.com | N7: Jean-Charles Basseguy +33-156763300 rso.france@orange.com +33-156763355 | O7: Jean-Charles Basseguy +33-156763300 rso.france@orange.com +33-156763355 | P7: Yes Link | Q7: BO Main desk/NBO security: +33146411004 | R7: CARREFOUR | S7: Size of the Building: N/A Size of the hosting area: 2236m² Capacity of the hosting area (# cabinets): 840 (roughly) Possible expansion: Y Size of expansion: 660m² | V7: 0 | W7: Unable to support requests for new business due to site closure and cost.
A8: EMEA | B8: France | C8: Paris | D8: Saint Denis | E8: Equinix | F8: XVP28 | G8: 114 rue ambroise Croizat 93200 Saint Denis | H8: Equinix PA3 | I8: 1 - Major | J8: Honey | L8: Equinix | M8: David Taieb Office : +33 1 40 91 36 39 Mobile : +33 6 81 87 76 63 david.taieb@orange.com | N8: David Taieb +33 1 40 91 36 39 +33 6 81 87 76 63 david.taieb@orange.com | P8: No | Q8: contact:01 84 88 34 96 Servicedesk.FR@eu.equinix.com | R8: HONEY GDF GFI | T8: ISAE 3402 - ISO 9001 ISO 27001 - PCI DSS | U8: TIER III | W8: 163
A9: EMEA | B9: France | C9: Paris | D9: Aubervilliers | E9: Equinix | F9: XVP38 | G9: 10 rue Waldeck Rochet Building 520 93300 Aubervilliers France | H9: Equinix PA6 | I9: 1 - Major | J9: Honey | L9: Equinix | M9: David Taieb Office : +33 1 40 91 36 39 Mobile : +33 6 81 87 76 63 david.taieb@orange.com | N9: David Taieb +33 1 40 91 36 39 +33 6 81 87 76 63 david.taieb@orange.com | P9: No | Q9: contact:01 84 88 34 96 Servicedesk.FR@eu.equinix.com | R9: HONEY | T9: ISAE 3402 - ISO 9001 ISO 27001 - PCI DSS | U9: TIER III | W9: 72
A10: EMEA | B10: France | C10: Paris | D10: Pantin | E10: Equinix | F10: XVP29 | G10: 110 Bis avenue du Général Leclerc 93500 Pantin | H10: Equinix PA4 | I10: 1 - Major | J10: Honey | L10: Equinix | M10: David Taieb Office : +33 1 40 91 36 39 Mobile : +33 6 81 87 76 63 david.taieb@orange.com | N10: David Taieb +33 1 40 91 36 39 +33 6 81 87 76 63 david.taieb@orange.com | P10: No | Q10: contact:01 84 88 34 96 Servicedesk.FR@eu.equinix.com | R10: HONEY GDF GFI | T10: ISAE 3402 - ISO 9001 ISO 27001 - PCI DSS | U10: TIER IV | W10: 188
A11: EMEA | B11: United Kingdom | C11: London | D11: London | E11: Equinix | F11: ITSH01/ITSH02 | G11: 8 Buckingham Avenue Slough Trading Estate – Slough Berkshire SL1 4AX | H11: Equinix LD5 | I11: 1 - Major | L11: Equinix | M11: David Taieb Office : +33 1 40 91 36 39 Mobile : +33 6 81 87 76 63 david.taieb@orange.com | N11: Dave Hogg Office - 44 2083214586 Mobile - 44-796-686-158 | O11: Dave Hogg Office - 44 2083214586 Mobile - 44-796-686-158 | P11: No | Q11: contact : +44 345 373 2999 ServiceDesk.UK@eu.equinix.com | R11: Simmons and Simmons, Ecobank, Cage OCB (BAT, Rio Tinto) | T11: ISAE 3402 - ISO 9001 ISO 27001 - PCI DSS ISAE 14001 - ISO 18001 ISO 5001 | U11: TIER III | W11: 12
A12: EMEA | B12: United Kingdom | C12: London | D12: Park Royal | E12: Equant | F12: LONX04/LONX05 | G12: Unit 2 - Ursula Lapp Ind Estate Park Royal Bay, Old Oak Lane London NW10 6UD | H12: Park Royal | I12: 1 - Major | J12: Full | K12: No | L12: FOIS | M12: David Taieb Office : +33 1 40 91 36 39 Mobile : +33 6 81 87 76 63 david.taieb@orange.com | N12: Dave Hogg Office - 44 2083214586 Mobile - 44-796-686-158 | O12: Dave Hogg Office - 44 2083214586 Mobile - 44-796-686-1580 | P12: Yes Link | Q12: contact : +44 208 607 4515 parkroyalsecurity@ssg-net.com | R12: BHP EQUANT IT&S Guoman Hotels Ltd | S12: Size of the Building: 2,000m2 Size of the hosting area: To be Confirmed Capacity of the hosting area (# cabinets): 374 | T12: ISAE 3402 | U12: TIER III | V12: 0 | W12: 36
A13: EMEA | B13: United Kingdom | C13: London | D13: Hounslow | E13: Equant | F13: LONH04/LONT04 | G13: 1st Floor Lampton House Lampton Road, Hounslow, TW3 4EY | H13: Equant Lampton House | I13: 3 - Opportunistic not to promote | J13: Full + Out dated | L13: FOIS | M13: David Taieb Office : +33 1 40 91 36 39 Mobile : +33 6 81 87 76 63 david.taieb@orange.com | N13: Dave Hogg Office - 44 2083214586 Mobile - 44-796-686-158 | O13: Dave Hogg Office - 44 2083214586 Mobile - 44-796-686-1581 | P13: Yes | Q13: Contact : +44 208 607 7626 lamptonhousesecurity@ssg-net.com | R13: EQUANT Ent IT | U13: TIER III
A14: EMEA | B14: Germany | C14: Frankfurt | D14: Frankfurt | E14: Equinix | F14: FRAT10 | G14: Equinix (IBX Services) GmbH, Lärchenstrasse 110, 65933 Frankfurt Griesheim Germany | H14: Equinix FR4 | I14: 1 - Major | J14: JCT services | K14: No | L14: Equinix | M14: David Taieb Office : +33 1 40 91 36 39 Mobile : +33 6 81 87 76 63 david.taieb@orange.com | N14: Thomas Kolbe Office : +49 6196962714 Mobile : +49 6196962123 thomas.kolbe@orange.com | O14: FOIS operational site GNMC-PAR /Supporting Site India SCC - WE Field Region / Field Engineer (FE) name: LEIB, Bernd Field Engineer (FE) contact number : +49 6196 96220/+49 172 6756368 | P14: connected to UHP Cesson (admin and monitoring) linked to Cesson / isolated network | Q14: security is controlled via Access List, only approved staff will get access to the DC. Access Cards will only be handed out to authorised staff managed via secure access list embeeded in customer portal / 24h in advance need normal DC management/maintenance visits need to be announced Contact : +49 1805 049 555 ServiceDesk.de@eu.equinix.com | R14: B2GaaS, SITA, Share Cloud, Siemens, Takeda, Additiv, ALDI | S14: 1500w/m² Power of the Diesel:8*1600 kVA diesel engine generators power of the UPS:4*1600 KVA Units in n+1 DC own power transformator available:4 * 2500 KVA | T14: ISAE 3402 - ISO 9001 ISO 27001 - PCI DSS ISAE 14001 - ISO 18001 ISO 5001 | U14: TIER III+ | V14: 0 | W14: 46
A15: EMEA | B15: Germany | C15: Frankfurt | D15: Frankfurt | E15: Equant | F15: FRAX01 | G15: Kleyerstrasse 90 60326 Frankfurt | H15: Equant FRAX01 | I15: 3 - Opportunistic not to promote | L15: FOIS | M15: David Taieb Office : +33 1 40 91 36 39 Mobile : +33 6 81 87 76 63 david.taieb@orange.com | N15: Thomas Kolbe Office : +49 6196962714 Mobile : +49 6196962123 thomas.kolbe@orange.com | P15: Yes | Q15: Contact : +49 6196 962203 | T15: ISO 9001 - ISO 27001 | U15: TIERIII
A16: EMEA | B16: Belgium | C16: Brussel | D16: Brussel | E16: Mobistar | F16: BRUT03 | G16: Mobistar Datacenter Nossegem Leuvensesteenweg 641,1930 Zaventem, Belgium | H16: Stuart DC | I16: 3 - Opportunistic not to promote | L16: Mobistar | M16: David Taieb Office : +33 1 40 91 36 39 Mobile : +33 6 81 87 76 63 david.taieb@orange.com | N16: Paul Meijer Office: +31 206069161 Mobile : +31 206069200 paul.meijer@orange.com | O16: Paul Meijer Office: +31 206069161 Mobile : +31 206069200 paul.meijer@orange.com | P16: No | Q16: Level 1 / +32 (0) 261 401 20 : Duty manager Level 2 / +32 (0) 261 401 55 : Operation Service Desk 24/7 Level 3 / +32 (0) 261 401 23 : Pepijn Palmas | T16: ISO 27001 | U16: TIERIII
A17: EMEA | B17: Netherlands | C17: Amsterdam | D17: Amsterdam | E17: Equinix | F17: AMST02 | G17: Equinix - Science Park 610 1098 XH Amsterdam The Netherlands | H17: Equinix AM3 | I17: 3 - Opportunistic not to promote | L17: Equinix | M17: David Taieb Office : +33 1 40 91 36 39 Mobile : +33 6 81 87 76 63 david.taieb@orange.com | N17: Paul Meijer Office: +31 206069161 Mobile : +31 206069200 paul.meijer@orange.com | P17: No | Q17: Contact : +31 20 808 0015 ServiceDesk.NL@eu.equinix.com | R17: General Electric International Inc | T17: ISAE 3402 - ISO 9001 ISO 27001 - PCI DSS ISAE 14001 - ISO 18001 ISO 5001 | U17: TIERIII
A18: EMEA | B18: Netherlands | C18: Amsterdam | D18: Amsterdam | E18: Equinix | F18: AMS15 | G18: Equinix - Amstel Business Park Campus Duivendrechtsekade 80A 1096 AH Amsterdam The Netherlands | H18: Equinix AM6 | I18: 1 - Major | L18: Equinix | M18: Olivier Coroller Office +33 2 23 06 44 62 Mobile +33 6 71 92 65 97 olivier.coroller@orange.com | N18: Paul Meijer Office: +31 206069161 Mobile : +31 206069200 paul.meijer@orange.com | O18: VERKRUISEN Roel Office: +31206069272 Mobile : +31653810114 roel.verkruisen@orange.com | P18: No | Q18: Contact : +31 20 808 0015 ServiceDesk.NL@eu.equinix.com | R18: Flexible Engine | T18: ISO 27001 - PCI-DSS -OHSAS 18001 - ISO 9001 - ISO 5001 - ISO 14001 - SSAE 16/ISAE 3402 SOC-1 Type II | U18: TIERIII | W18: 86
A19: EMEA | B19: Netherlands | C19: Amsterdam | D19: Amsterdam | E19: Equant | F19: AMSX01 | G19: Cessnalaan 71, 1119 NM, Schiphol-Rijk The Netherlands | H19: Amsterdam AMSX01 | I19: 1 - Major | L19: FOIS | M19: David Taieb Office : +33 1 40 91 36 39 Mobile : +33 6 81 87 76 63 david.taieb@orange.com | N19: Paul Meijer Office: +31 206069161 Mobile : +31 206069200 paul.meijer@orange.com | O19: VERKRUISEN Roel Office: +31206069272 Mobile : +31653810114 roel.verkruisen@orange.com | P19: No | Q19: Contact : +31 20 808 0015 | T19: ISO 9001 - ISO 27001 | U19: TIERIII+ | W19: 86
A20: EMEA | B20: Switzerland | C20: Geneva | D20: Geneva | E20: Equinix | F20: GVAT02 | G20: Equinix - 48, Route du Bois-des-Frères 1219 Le Lignon Switzerland | H20: Equinix GV2 | I20: 3 - Opportunistic not to promote | J20: Nethosting | L20: Equinix | M20: David Taieb Office : +33 1 40 91 36 39 Mobile : +33 6 81 87 76 63 david.taieb@orange.com | N20: Pierre Mall Office: +41 223399155 Mobile : +41 794269190 pierre.mall@orange.com | O20: Pierre Mall Office: +41 223399155 Mobile : +41 794269190 pierre.mall@orange.com | P20: connected to UHP Cesson | Q20: Contact : +41 22 518 07 20 ServiceDesk.CH@eu.equinix.com | T20: ISO 9001 - ISO 27001 ISAE 3402 - PCI DSS | U20: TIERIII
